<?xml version="1.0" encoding="UTF-8"?>
<testng-results skipped="0" failed="1" ignored="0" total="2" passed="1">
  <reporter-output>
  </reporter-output>
  <suite name="Default suite" duration-ms="22064" started-at="2019-11-28T11:25:30 PKT" finished-at="2019-11-28T11:25:53 PKT">
    <groups>
    </groups>
    <test name="Default test" duration-ms="22064" started-at="2019-11-28T11:25:30 PKT" finished-at="2019-11-28T11:25:53 PKT">
      <class name="apidemospackage.mixed">
        <test-method status="PASS" signature="tc_one()[pri:0, instance:apidemospackage.mixed@1139b2f3]" name="tc_one" duration-ms="21955" started-at="2019-11-28T11:25:30 PKT" finished-at="2019-11-28T11:25:52 PKT">
          <reporter-output>
          </reporter-output>
        </test-method> <!-- tc_one -->
        <test-method status="FAIL" signature="tc_two()[pri:0, instance:apidemospackage.mixed@1139b2f3]" name="tc_two" duration-ms="4" started-at="2019-11-28T11:25:53 PKT" finished-at="2019-11-28T11:25:53 PKT">
          <exception class="java.lang.AssertionError">
            <message>
              <![CDATA[fail test did not expect to find [false] but found [true]]]>
            </message>
            <full-stacktrace>
              <![CDATA[java.lang.AssertionError: fail test did not expect to find [false] but found [true]
at org.testng.Assert.fail(Assert.java:97)
at org.testng.Assert.failNotEquals(Assert.java:969)
at org.testng.Assert.assertFalse(Assert.java:65)
at apidemospackage.mixed.tc_two(mixed.java:148)
at sun.reflect.NativeMethodAccessorImpl.invoke0(Native Method)
at sun.reflect.NativeMethodAccessorImpl.invoke(Unknown Source)
at sun.reflect.DelegatingMethodAccessorImpl.invoke(Unknown Source)
at java.lang.reflect.Method.invoke(Unknown Source)
at org.testng.internal.MethodInvocationHelper.invokeMethod(MethodInvocationHelper.java:133)
at org.testng.internal.TestInvoker.invokeMethod(TestInvoker.java:584)
at org.testng.internal.TestInvoker.invokeTestMethod(TestInvoker.java:172)
at org.testng.internal.MethodRunner.runInSequence(MethodRunner.java:46)
at org.testng.internal.TestInvoker$MethodInvocationAgent.invoke(TestInvoker.java:804)
at org.testng.internal.TestInvoker.invokeTestMethods(TestInvoker.java:145)
at org.testng.internal.TestMethodWorker.invokeTestMethods(TestMethodWorker.java:146)
at org.testng.internal.TestMethodWorker.run(TestMethodWorker.java:128)
at java.util.ArrayList.forEach(Unknown Source)
at org.testng.TestRunner.privateRun(TestRunner.java:770)
at org.testng.TestRunner.run(TestRunner.java:591)
at org.testng.SuiteRunner.runTest(SuiteRunner.java:402)
at org.testng.SuiteRunner.runSequentially(SuiteRunner.java:396)
at org.testng.SuiteRunner.privateRun(SuiteRunner.java:355)
at org.testng.SuiteRunner.run(SuiteRunner.java:304)
at org.testng.SuiteRunnerWorker.runSuite(SuiteRunnerWorker.java:53)
at org.testng.SuiteRunnerWorker.run(SuiteRunnerWorker.java:96)
at org.testng.TestNG.runSuitesSequentially(TestNG.java:1180)
at org.testng.TestNG.runSuitesLocally(TestNG.java:1102)
at org.testng.TestNG.runSuites(TestNG.java:1032)
at org.testng.TestNG.run(TestNG.java:1000)
at org.testng.remote.AbstractRemoteTestNG.run(AbstractRemoteTestNG.java:115)
at org.testng.remote.RemoteTestNG.initAndRun(RemoteTestNG.java:251)
at org.testng.remote.RemoteTestNG.main(RemoteTestNG.java:77)
]]>
            </full-stacktrace>
          </exception> <!-- java.lang.AssertionError -->
          <reporter-output>
          </reporter-output>
        </test-method> <!-- tc_two -->
      </class> <!-- apidemospackage.mixed -->
    </test> <!-- Default test -->
  </suite> <!-- Default suite -->
</testng-results>
